<?xml version="1.0" ?>
<robot name="wyf">

<!-- /////////////////////////////////////    COLOR    ///////////////////////////////////////////// -->
	<material name="Black">
		<color rgba="0 0 0 1"/>
	</material>
	<material name="White">
		<color rgba="1 1 1 1"/>
	</material>
	<material name="Blue">
		<color rgba="0 0 1 1"/>
	</material>
	<material name="Red">
		<color rgba="1 0 0 1"/>
	</material>
	 <material name="Yellow">
        <color rgba="1 0.4 0 1"/>
    </material>


<!-- /////////////////////////////////////    BASE    ///////////////////////////////////////////// -->
    <link name="base_footprint">
                  <visual>
                        <geometry>
                                <box size="0.001 0.001 0.001" />
                        </geometry>
                </visual>
        </link>

<joint name="base_footprint_link" type="fixed">
                <parent link="base_footprint" />
                <child link="base_link" />
                <origin xyz="0 0 0.05" rpy="0 0 0" />
        </joint>


    <link name="base_link">
        <visual>
            <origin xyz=" 0 0 0" rpy="0 0 0" />
            <geometry>
                <box size="0.5 0.4 0.1" />
            </geometry>
            <material name="Yellow"/>
        </visual>
    </link>


<!-- /////////////////////////////////////    WHEEL    ///////////////////////////////////////////// -->

    <link name="left_wheel1_link">
        <visual>
            <origin xyz="0 0 0" rpy="1.5707 0 0" />
            <geometry>
                <cylinder radius="0.06" length = "0.025"/>
            </geometry>
            <material name="Black"/>
        </visual>
    </link>

    <joint name="left_wheel1_joint" type="continuous">
    <!-- /////相对于底盘的位置，左0.19，前0.18，下降0.05//// -->
        <origin xyz="0.18 0.19 -0.05" rpy="0 0 0"/>
        <parent link="base_link"/>
        <child link="left_wheel1_link"/>
        <axis xyz="0 1 0"/>
    </joint>


    <link name="left_wheel2_link">
        <visual>
            <origin xyz="0 0 0" rpy="1.5707 0 0" />
            <geometry>
                <cylinder radius="0.06" length = "0.025"/>
            </geometry>
            <material name="Black"/>
        </visual>
    </link>

    <joint name="left_wheel2_joint" type="continuous">
        <origin xyz="-0.18 0.19 -0.05" rpy="0 0 0"/>
        <parent link="base_link"/>
        <child link="left_wheel2_link"/>
        <axis xyz="0 1 0"/>
    </joint>

 <link name="right_wheel1_link">
        <visual>
          <origin xyz="0 0 0" rpy="1.5707 0 0" />  
            <geometry>
                <cylinder radius="0.06" length = "0.025"/>
            </geometry>
            <material name="Black"/>
        </visual>
    </link>

    <joint name="right_wheel1_joint" type="continuous">
        <origin xyz="0.18 -0.19 -0.05" rpy="0 0 0"/>
        <parent link="base_link"/>
        <child link="right_wheel1_link"/>
        <axis xyz="0 0 1"/>
    </joint>

 <link name="right_wheel2_link">
        <visual>
            <origin xyz="0 0 0" rpy="1.5707 0 0" />
            <geometry>
                <cylinder radius="0.06" length = "0.025"/>
            </geometry>
            <material name="Black"/>
        </visual>
    </link>

    <joint name="right_wheel2_joint" type="continuous">
        <origin xyz="-0.18 -0.19 -0.05" rpy="0 0 0"/>
        <parent link="base_link"/>
        <child link="right_wheel2_link"/>
        <axis xyz="0 1 0"/>
    </joint>

<!-- //////////////////////////////////////////
    pole 支柱  ////////////////////////////////////////// -->

    <link name="left_pole1_link">
        <visual>
            <origin xyz="0 0 0" rpy="0 0 0" />
            <geometry>
                <box size="0.02 0.02 0.4" />
            </geometry>
            <material name="White"/>
        </visual>
    </link>

    <joint name="left_pole1_joint" type="fixed">
        <origin xyz=" 0.23 0.18 0.2" rpy="0 0 0"/>
        <parent link="base_link"/>
        <child link="left_pole1_link"/>
        <axis xyz="0 1 0"/>
    </joint>

    <link name="left_pole2_link">
        <visual>
            <origin xyz="0 0 0" rpy="0 0 0" />
            <geometry>
                <box size="0.02 0.02 0.4" />
            </geometry>
            <material name="White"/>
        </visual>
    </link>

    <joint name="left_pole2_joint" type="fixed">
        <origin xyz=" -0.23 0.18 0.2" rpy="0 0 0"/>
        <parent link="base_link"/>
        <child link="left_pole2_link"/>
        <axis xyz="0 1 0"/>
    </joint>

    <link name="right_pole1_link">
        <visual>
            <origin xyz="0 0 0" rpy="0 0 0" />
            <geometry>
                <box size="0.02 0.02 0.4" />
            </geometry>
            <material name="White"/>
        </visual>
    </link>

    <joint name="right_pole1_joint" type="fixed">
        <origin xyz=" 0.23 -0.18 0.2" rpy="0 0 0"/>
        <parent link="base_link"/>
        <child link="right_pole1_link"/>
        <axis xyz="0 1 0"/>
    </joint>
    
     <link name="right_pole2_link">
        <visual>
            <origin xyz="0 0 0" rpy="0 0 0" />
            <geometry>
                <box size="0.02 0.02 0.4" />
            </geometry>
            <material name="White"/>
        </visual>
    </link>

    <joint name="right_pole2_joint" type="fixed">
        <origin xyz=" -0.23 -0.18 0.2" rpy="0 0 0"/>
        <parent link="base_link"/>
        <child link="right_pole2_link"/>
        <axis xyz="0 1 0"/>
    </joint>   
<!-- /////////////////////////////////////  
  UP 顶板   ///////////////////////////////////////////// -->
    <link name="up_link">
        <visual>
            <origin xyz=" 0 0 0" rpy="0 0 0" />
            <geometry>
                <box size="0.5 0.4 0.05" />
            </geometry>
            <material name="Yellow"/>
        </visual>
    </link>
  
     <joint name="up_pole_joint" type="fixed">
        <origin xyz="0 0 0.4" rpy="0 0 0"/>
        <parent link="base_link"/>
        <child link="up_link"/>
        <axis xyz="0 1 0"/>
    </joint>   
     
 <!-- /////////////////////////////////////    KINECT    ///////////////////////////////////////////// -->
    <link name="kinect_link">
        <visual>
            <origin xyz="0 0 0" rpy="0 0 1.5708"/>
            <geometry>
                <mesh filename="package://wyf_description/meshes/kinect.dae" />
            </geometry>
        </visual>
    </link>

    <joint name="kinect_joint" type="fixed">
   <!-- ////注意这里是kinect相对于顶板up 的高度位置/// -->  
        <origin xyz="0.15 0 0.05" rpy="0 0 0"/>
        <parent link="up_link"/>
        <child link="kinect_link"/>
    </joint>
   
<!-- /////////////////////////////////////    LASER    ///////////////////////////////////////////// -->
    <link name="laser_link">
		<visual>
			<origin xyz="0 0 0" rpy="0 0 0" />
			<geometry>
				<cylinder length="0.08" radius="0.07"/>
			</geometry>
			<material name="Black"/>
		</visual>
    </link>

    <joint name="laser_joint" type="fixed">
        <origin xyz="-0.08 0 0.06" rpy="0 0 0"/>
        <parent link="up_link"/>
        <child link="laser_link"/>
    </joint>
    
</robot>
